Workbook

Sheet README
A1: betterwaste.co.uk — New Keyword Opportunities
A3: Date | B3: 1 October 2026
A4: Market | B4: UK
A5: Data source | B5: Semrush UK database — search volume, Keyword Difficulty, search intent, current rankings, and the Authority Score of every ranking competitor. CPC is not included.
A6: Ahrefs use | B6: Page existence and HTTP status only (the environment cannot reach betterwaste.co.uk directly). No Ahrefs metric appears in this workbook.
A8: TABS
A9: Opportunities | B9: 133 NEW keywords only. Nothing from your existing KW/URL mapping sheet is repeated here — the three that overlapped (commercial waste collection london / manchester / birmingham) were removed.
A10: Page Summary | B10: One row per target page, with live formulas counting keywords and summing volume from Master Plan.
A11: Fix List | B11: 15 technical and mapping fixes found during the audit.
A12: Page Inventory | B12: What actually exists on the site, including pages previously assumed missing.
A14: DIFFICULTY GRADING
A15: Benchmark | B15: Better Waste is Semrush Authority Score 20. The test: how many sites at AS 25 or below — at or below Better Waste — currently rank in the top 10?
A16: EASY | B16: 3+ ranking sites at AS 25 or below, and fewer than 4 council/gov slots. Reachable on content quality.
A17: MEDIUM | B17: 1–2 at AS 25 or below, or lowest AS is 26–30 with fewer than 4 council/gov slots. Needs a strong page plus links.
A18: HARD | B18: Nothing at AS 25 or below, or 4+ council/gov slots. Defer until authority improves.
A19: AVOID | B19: SERP intent is not a commercial waste service (household, council or retail intent). Do not target.
A21: EVIDENCE
A22: Coverage | B22: All 104 recommendations are graded: 36 from a direct SERP + Authority Score check, 68 inherited from a directly-checked keyword on the same SERP (the Evidence column names which).
A23: Gap check | B23: Competitor gap passes against thefirstmile.co.uk, businesswaste.co.uk, divert.co.uk and recorra.co.uk added 42 keywords in seven clusters with no prior coverage: pest/bin hygiene, abbreviated bin specs, skips, legislation/news, compliance, shredding/data destruction and other streams.
A24: Exclusions | B24: Every keyword in your existing sheet is excluded, including token-identical variants (e.g. "mixed dry recycling" was dropped because your sheet has "dry mixed recycling"). Four were removed on that basis.
A25: Rejected on checking | B25: Six candidates were checked and rejected rather than added as opportunities: food waste caddy and waste compactor and baler machine (retail/equipment SERPs), fridge freezer disposal and fridge removal (household), and house clearance (residential). medical waste collection and weee waste were added but graded AVOID/HARD so the decision is visible rather than silent.
A27: KNOWN LIMITATION
A28: Formulas | B28: The Keywords, Total SV and Already Ranking columns on Page Summary are live COUNTIF/SUMIF formulas. They show no value until Excel opens and recalculates the file — that is expected. Best Position is a static snapshot of current Semrush rankings, not a formula.
A29: Not verified | B29: The Manchester / London / Birmingham city URLs return 301 while the "-old" equivalents return 200. Confirm where those redirects point before acting — see the Fix List.

Sheet Opportunities
A1: Market | B1: Type | C1: Cluster | D1: Page | E1: Page Status | F1: Keyword | G1: Intent | H1: SV (Semrush UK) | I1: KD | J1: Current Position | K1: Current Ranking URL | L1: Difficulty | M1: Evidence (Authority Score) | N1: Priority | O1: Notes
A2: UK | B2: Gap vs competitors | C2: G - Skips | D2: https://betterwaste.co.uk/commercial-skip-hire/ | E2: CREATE | F2: skip sizes uk | G2: Informational | H2: 2900 | I2: 9 | L2: EASY | M2: AS 24 (tomwhitewaste), 12 (budgetskipsdirect), 12 (enterprise-skiphire), 11 (thewastemonkeys) - four sub-25 sites. CHECK SERVICE FIT: does Better Waste offer skips? | N2: P2 | O2: CHECK SERVICE FIT before building
A3: UK | B3: Gap vs competitors | C3: G - Other streams | D3: https://betterwaste.co.uk/office-waste-management/ | E3: OPTIMISE | F3: office clearance | G3: Commercial | H3: 2400 | I3: 14 | L3: EASY | M3: inherited from "office waste management": stale SERP: half the top 10 are http:// URLs, one is a US state agency; AS 24 at or below Better Waste (AS 20); 1 council/gov slots | N3: P1 | O3: thefirstmile.co.uk ranks p3
A4: UK | B4: Gap vs competitors | C4: G - Skips | D4: https://betterwaste.co.uk/commercial-skip-hire/ | E4: CREATE | F4: dimensions of skips | G4: Informational | H4: 1900 | I4: 9 | L4: EASY | M4: inherited from "skip sizes uk": AS 24 (tomwhitewaste), 12 (budgetskipsdirect), 12 (enterprise-skiphire), 11 (thewastemonkeys) - four sub-25 sites. CHECK SERVICE FIT: does Better Waste offer skips? | N4: P2 | O4: CHECK SERVICE FIT
A5: UK | B5: Gap vs competitors | C5: G - Other streams | D5: https://betterwaste.co.uk/it-equipment-disposal/ | E5: CREATE | F5: digital waste | G5: Informational | H5: 1900 | I5: 22 | L5: EASY | M5: inherited from "it equipment disposal": AS 8, 19, 19, 20, 20 at or below Better Waste (AS 20) | N5: P3 | O5: thefirstmile.co.uk ranks p3
A6: UK | B6: Gap vs competitors | C6: G - Bin specs (abbreviated) | D6: https://betterwaste.co.uk/bins/240l-bin/ | E6: OPTIMISE | F6: 240 litre wheelie bin | G6: Informational + Transactional | H6: 1600 | I6: 8 | L6: EASY | M6: inherited from "1100l bin": AS 13 (wheeliebinwarehouse), 12 (sgmwastemanagement), 22 (bins.co.uk) at or below Better Waste - and the /bins/1100l-bin/ page already exists | N6: P1 | O6: Page already exists; businesswaste ranks p9 | This is the form to target on this page (distinct SERP from the spelled-out variant).
A7: UK | B7: Waste Type | C7: B - Missing streams | D7: https://betterwaste.co.uk/sanitary-waste/ | E7: CREATE | F7: sanitary waste disposal | G7: Informational | H7: 1300 | I7: 10 | L7: EASY | M7: inherited from "sanitary waste collection": AS 9, 9, 13, 21 at or below Better Waste (AS 20) | N7: P1 | O7: BEST ROI - lowest KD highest value. businesswaste p3
A8: UK | B8: Waste Type | C8: B - Missing streams | D8: https://betterwaste.co.uk/sanitary-waste/ | E8: CREATE | F8: sanitary waste collection | G8: Commercial | H8: 1300 | I8: 17 | L8: EASY | M8: AS 9, 9, 13, 21 at or below Better Waste (AS 20) | N8: P1 | O8: businesswaste.co.uk p4
A9: UK | B9: Gap vs competitors | C9: G - Skips | D9: https://betterwaste.co.uk/commercial-skip-hire/ | E9: CREATE | F9: commercial skip hire | G9: Commercial | H9: 1300 | I9: 11 | L9: EASY | M9: inherited from "skip sizes uk": AS 24 (tomwhitewaste), 12 (budgetskipsdirect), 12 (enterprise-skiphire), 11 (thewastemonkeys) - four sub-25 sites. CHECK SERVICE FIT: does Better Waste offer skips? | N9: P2 | O9: CHECK SERVICE FIT
A10: UK | B10: Gap vs competitors | C10: G - Skips | D10: https://betterwaste.co.uk/commercial-skip-hire/ | E10: CREATE | F10: skip dimensions uk | G10: Informational | H10: 1300 | I10: 11 | L10: EASY | M10: inherited from "skip sizes uk": AS 24 (tomwhitewaste), 12 (budgetskipsdirect), 12 (enterprise-skiphire), 11 (thewastemonkeys) - four sub-25 sites. CHECK SERVICE FIT: does Better Waste offer skips? | N10: P3 | O10: CHECK SERVICE FIT
A11: UK | B11: Gap vs competitors | C11: G - Shredding & data | D11: https://betterwaste.co.uk/confidential-waste/ | E11: CREATE | F11: document shredding | G11: Commercial | H11: 1300 | I11: 25 | L11: EASY | M11: simply-shredding AS 16 and doxbond AS 10 both rank, alongside homeshreduk, shredstation, sdsecureshredding and goshred - the same small-operator set as confidential waste collection | N11: P1 | O11: Small shredders dominate; Restore AS 37 is the only large player
A12: UK | B12: Waste Type | C12: B - Missing streams | D12: https://betterwaste.co.uk/confidential-waste/ | E12: CREATE | F12: confidential waste collection | G12: Commercial | H12: 1000 | I12: 13 | L12: EASY | M12: AS 6, 9, 10, 16 at or below Better Waste (AS 20) | N12: P1 | O12: Very low KD
A13: UK | B13: Waste Type | C13: B - Missing streams | D13: https://betterwaste.co.uk/confidential-waste/ | E13: CREATE | F13: confidential shredding | G13: Commercial | H13: 1000 | I13: 16 | L13: EASY | M13: inherited from "confidential waste collection": AS 6, 9, 10, 16 at or below Better Waste (AS 20) | N13: P1
A14: UK | B14: Gap vs competitors | C14: G - Bin specs (abbreviated) | D14: https://betterwaste.co.uk/bins/1100l-bin/ | E14: OPTIMISE | F14: 1100l wheelie bin | G14: Informational | H14: 1000 | I14: 12 | L14: EASY | M14: inherited from "1100l bin": AS 13 (wheeliebinwarehouse), 12 (sgmwastemanagement), 22 (bins.co.uk) at or below Better Waste - and the /bins/1100l-bin/ page already exists | N14: P1 | O14: Page already exists; businesswaste ranks p5 | This is the form to target on this page (distinct SERP from the spelled-out variant).
A15: UK | B15: Gap vs competitors | C15: G - Bin specs (abbreviated) | D15: https://betterwaste.co.uk/binpedia/ | E15: OPTIMISE | F15: wheelie bin sizes | G15: Informational | H15: 1000 | I15: 10 | L15: EASY | M15: inherited from "1100l bin": AS 13 (wheeliebinwarehouse), 12 (sgmwastemanagement), 22 (bins.co.uk) at or below Better Waste - and the /bins/1100l-bin/ page already exists | N15: P1 | O15: businesswaste ranks p8 | This is the form to target on this page (distinct SERP from the spelled-out variant).
A16: UK | B16: Gap vs competitors | C16: G - Other streams | D16: https://betterwaste.co.uk/paper-and-cardboard-waste/ | E16: OPTIMISE | F16: cardboard recycling collection | G16: Commercial | H16: 1000 | I16: 10 | L16: EASY | M16: inherited from "business cardboard recycling": AS 16, 18, 20 at or below Better Waste (AS 20) | N16: P2 | O16: Map to paper/cardboard page; thefirstmile ranks p2
A17: UK | B17: Gap vs competitors | C17: G - Other streams | D17: https://betterwaste.co.uk/paper-and-cardboard-waste/ | E17: OPTIMISE | F17: paper recycling | G17: Commercial | H17: 1000 | I17: 19 | L17: EASY | M17: inherited from "business cardboard recycling": AS 16, 18, 20 at or below Better Waste (AS 20) | N17: P2 | O17: thefirstmile.co.uk ranks p5
A18: UK | B18: Gap vs competitors | C18: G - Other streams | D18: https://betterwaste.co.uk/dry-mixed-recycling-waste/ | E18: OPTIMISE | F18: soft plastic recycling | G18: Informational | H18: 1000 | I18: 18 | L18: EASY | M18: inherited from "business cardboard recycling": AS 16, 18, 20 at or below Better Waste (AS 20) | N18: P3 | O18: thefirstmile.co.uk ranks p3
A19: UK | B19: Gap vs competitors | C19: G - Bin specs (abbreviated) | D19: https://betterwaste.co.uk/bins/660l-bin/ | E19: OPTIMISE | F19: 660l bin | G19: Informational | H19: 880 | I19: 9 | L19: EASY | M19: inherited from "1100l bin": AS 13 (wheeliebinwarehouse), 12 (sgmwastemanagement), 22 (bins.co.uk) at or below Better Waste - and the /bins/1100l-bin/ page already exists | N19: P1 | O19: Page already exists; businesswaste ranks p4 | This is the form to target on this page (distinct SERP from the spelled-out variant).
A20: UK | B20: Gap vs competitors | C20: G - Bin specs (abbreviated) | D20: https://betterwaste.co.uk/bins/660l-bin/ | E20: OPTIMISE | F20: 660 litre wheelie bin | G20: Informational | H20: 880 | I20: 6 | L20: EASY | M20: inherited from "1100l bin": AS 13 (wheeliebinwarehouse), 12 (sgmwastemanagement), 22 (bins.co.uk) at or below Better Waste - and the /bins/1100l-bin/ page already exists | N20: P1 | O20: Page already exists; businesswaste ranks p6 | This is the form to target on this page (distinct SERP from the spelled-out variant).
A21: UK | B21: Gap vs competitors | C21: G - Bin specs (abbreviated) | D21: https://betterwaste.co.uk/bins/1100l-bin/ | E21: OPTIMISE | F21: 1100l bin | G21: Informational | H21: 880 | I21: 11 | L21: EASY | M21: AS 13 (wheeliebinwarehouse), 12 (sgmwastemanagement), 22 (bins.co.uk) at or below Better Waste - and the /bins/1100l-bin/ page already exists | N21: P1 | O21: Page already exists; businesswaste ranks p4 | This is the form to target on this page (distinct SERP from the spelled-out variant).
A22: UK | B22: Gap vs competitors | C22: G - Shredding & data | D22: https://betterwaste.co.uk/confidential-waste/ | E22: CREATE | F22: secure data destruction | G22: Informational | H22: 880 | I22: 9 | L22: EASY | M22: inherited from "document shredding": simply-shredding AS 16 and doxbond AS 10 both rank, alongside homeshreduk, shredstation, sdsecureshredding and goshred - the same small-operator set as confidential waste collection | N22: P1 | O22: recorra ranks p6. KD 9
A23: UK | B23: Gap vs competitors | C23: G - Other streams | D23: https://betterwaste.co.uk/paper-and-cardboard-waste/ | E23: OPTIMISE | F23: commercial cardboard recycling | G23: Commercial | H23: 880 | I23: 16 | L23: EASY | M23: inherited from "business cardboard recycling": AS 16, 18, 20 at or below Better Waste (AS 20) | N23: P2 | O23: recorra.co.uk ranks p8
A24: UK | B24: Gap vs competitors | C24: G - Bin specs (abbreviated) | D24: https://betterwaste.co.uk/bins/360l-bin/ | E24: OPTIMISE | F24: 360l bin | G24: Commercial | H24: 720 | I24: 9 | L24: EASY | M24: inherited from "1100l bin": AS 13 (wheeliebinwarehouse), 12 (sgmwastemanagement), 22 (bins.co.uk) at or below Better Waste - and the /bins/1100l-bin/ page already exists | N24: P2 | O24: Page already exists; businesswaste ranks p4 | This is the form to target on this page (distinct SERP from the spelled-out variant).
A25: UK | B25: Gap vs competitors | C25: G - Skips | D25: https://betterwaste.co.uk/commercial-skip-hire/ | E25: CREATE | F25: 2 yard skip size | G25: Informational | H25: 720 | I25: 8 | L25: EASY | M25: inherited from "skip sizes uk": AS 24 (tomwhitewaste), 12 (budgetskipsdirect), 12 (enterprise-skiphire), 11 (thewastemonkeys) - four sub-25 sites. CHECK SERVICE FIT: does Better Waste offer skips? | N25: P3 | O25: CHECK SERVICE FIT
A26: UK | B26: Gap vs competitors | C26: G - Shredding & data | D26: https://betterwaste.co.uk/confidential-waste/ | E26: CREATE | F26: hard drive destruction | G26: Transactional | H26: 720 | I26: 9 | L26: EASY | M26: inherited from "document shredding": simply-shredding AS 16 and doxbond AS 10 both rank, alongside homeshreduk, shredstation, sdsecureshredding and goshred - the same small-operator set as confidential waste collection | N26: P1 | O26: Transactional intent, KD 9
A27: UK | B27: Waste Type | C27: B - Missing streams | D27: https://betterwaste.co.uk/it-equipment-disposal/ | E27: CREATE | F27: it equipment disposal | G27: Commercial | H27: 590 | I27: 37 | L27: EASY | M27: AS 8, 19, 19, 20, 20 at or below Better Waste (AS 20) | N27: P3
A28: UK | B28: Gap vs competitors | C28: G - Shredding & data | D28: https://betterwaste.co.uk/confidential-waste/ | E28: CREATE | F28: shredding service | G28: Commercial | H28: 590 | I28: 20 | L28: EASY | M28: inherited from "document shredding": simply-shredding AS 16 and doxbond AS 10 both rank, alongside homeshreduk, shredstation, sdsecureshredding and goshred - the same small-operator set as confidential waste collection | N28: P2
A29: UK | B29: Service | C29: A - Core commercial | D29: https://betterwaste.co.uk/office-waste-management/ | E29: OPTIMISE | F29: office waste collection | G29: Commercial | H29: 390 | I29: 34 | J29: 65 | K29: https://betterwaste.co.uk/areas-we-cover/ | L29: EASY | M29: inherited from "office waste management": stale SERP: half the top 10 are http:// URLs, one is a US state agency; AS 24 at or below Better Waste (AS 20); 1 council/gov slots | N29: P2
A30: UK | B30: Waste Type | C30: B - Missing streams | D30: https://betterwaste.co.uk/wood-waste/ | E30: CREATE | F30: wood waste collection | G30: Commercial | H30: 390 | I30: 9 | L30: EASY | M30: AS 9, 11, 18, 22 at or below Better Waste (AS 20) | N30: P2 | O30: Very low KD
A31: UK | B31: Sector | C31: E - New sectors | D31: https://betterwaste.co.uk/office-waste-management/ | E31: OPTIMISE | F31: office waste management | G31: Commercial | H31: 390 | I31: 13 | L31: EASY | M31: stale SERP: half the top 10 are http:// URLs, one is a US state agency; AS 24 at or below Better Waste (AS 20); 1 council/gov slots | N31: P1
A32: UK | B32: Waste Type | C32: Sheet gap | D32: https://betterwaste.co.uk/paper-and-cardboard-waste/ | E32: OPTIMISE | F32: business cardboard recycling | G32: Informational | H32: 390 | I32: 16 | J32: 63 | K32: https://betterwaste.co.uk/paper-and-cardboard-waste/ | L32: EASY | M32: AS 16, 18, 20 at or below Better Waste (AS 20) | N32: P2 | O32: Not in sheet. Currently p63
A33: UK | B33: Waste Type | C33: B - Missing streams | D33: https://betterwaste.co.uk/cooking-oil-collection/ | E33: CREATE | F33: used cooking oil collection | G33: Commercial | H33: 320 | I33: 15 | L33: EASY | M33: AS 2, 6, 7, 19, 19 at or below Better Waste (AS 20) | N33: P3 | O33: Pairs with existing food waste pages
A34: UK | B34: Gap vs competitors | C34: G - Shredding & data | D34: https://betterwaste.co.uk/confidential-waste/ | E34: CREATE | F34: commercial shredding | G34: Commercial | H34: 320 | I34: 14 | L34: EASY | M34: inherited from "document shredding": simply-shredding AS 16 and doxbond AS 10 both rank, alongside homeshreduk, shredstation, sdsecureshredding and goshred - the same small-operator set as confidential waste collection | N34: P2
A35: UK | B35: Waste Type | C35: B - Missing streams | D35: https://betterwaste.co.uk/metal-waste/ | E35: CREATE | F35: metal waste collection | G35: Commercial | H35: 260 | I35: 24 | L35: EASY | M35: AS 9, 11, 15, 17, 20 at or below Better Waste (AS 20) - five scrap merchants. CHECK SERVICE MODEL: these sites buy scrap, they do not sell collection | N35: P3
A36: UK | B36: Sector | C36: E - New sectors | D36: https://betterwaste.co.uk/retail-waste-management/ | E36: OPTIMISE | F36: retail waste management | G36: Informational | H36: 260 | I36: 17 | J36: 45 | K36: https://betterwaste.co.uk/retail-waste-management/ | L36: EASY | M36: inherited from "office waste management": stale SERP: half the top 10 are http:// URLs, one is a US state agency; AS 24 at or below Better Waste (AS 20); 1 council/gov slots | N36: P2
A37: UK | B37: Sector | C37: E - New sectors | D37: https://betterwaste.co.uk/butchers-waste-collection/ | E37: CREATE | F37: butchers waste collection | G37: Informational + Transactional | H37: 260 | I37: 7 | L37: EASY | M37: AS 10, 10, 24 at or below Better Waste (AS 20); 1 council/gov slots | N37: P1 | O37: wastemanaged.co.uk p4. Lowest KD in cluster
A38: UK | B38: Sector | C38: E - Existing push | D38: https://betterwaste.co.uk/hair-salon-waste-management/ | E38: OPTIMISE | F38: salon waste management | G38: Informational | H38: 260 | I38: 6 | J38: 21 | K38: https://betterwaste.co.uk/hair-salon-waste-management/ | L38: EASY | M38: inherited from "butchers waste collection": AS 10, 10, 24 at or below Better Waste (AS 20); 1 council/gov slots | N38: P1 | O38: Currently p21
A39: UK | B39: Location | C39: F - Locations | D39: https://betterwaste.co.uk/areas-we-cover/leeds/ | E39: OPTIMISE | F39: commercial waste collection leeds | G39: Commercial | H39: 260 | I39: 17 | L39: EASY | M39: AS 13, 21, 21, 24, 25 at or below Better Waste (AS 20); 2 council/gov slots | N39: P1
A40: UK | B40: Location | C40: F - Locations | D40: https://betterwaste.co.uk/areas-we-cover/liverpool/ | E40: CREATE | F40: commercial waste collection liverpool | G40: Commercial | H40: 260 | I40: 18 | L40: EASY | M40: inherited from "commercial waste collection leeds": AS 13, 21, 21, 24, 25 at or below Better Waste (AS 20); 2 council/gov slots | N40: P1 | O40: No page exists
...

Sheet Page Summary
A1: Page | B1: Type | C1: Page Status | D1: Page Difficulty | E1: Keywords | F1: Total SV | G1: Already Ranking | H1: Best Position (snapshot)
A2: https://betterwaste.co.uk/areas-we-cover/bristol/ | B2: Location | C2: OPTIMISE | D2: EASY | E2: =COUNTIF('Opportunities'!$D$2:$D$143,$A2) | F2: =SUMIF('Opportunities'!$D$2:$D$143,$A2,'Opportunities'!$H$2:$H$143) | G2: =COUNTIFS('Opportunities'!$D$2:$D$143,$A2,'Opportunities'!$J$2:$J$143,">0") | H2: -
A3: https://betterwaste.co.uk/areas-we-cover/glasgow/ | B3: Location | C3: CREATE | D3: EASY | E3: =COUNTIF('Opportunities'!$D$2:$D$143,$A3) | F3: =SUMIF('Opportunities'!$D$2:$D$143,$A3,'Opportunities'!$H$2:$H$143) | G3: =COUNTIFS('Opportunities'!$D$2:$D$143,$A3,'Opportunities'!$J$2:$J$143,">0") | H3: -
A4: https://betterwaste.co.uk/areas-we-cover/leeds/ | B4: Location | C4: OPTIMISE | D4: EASY | E4: =COUNTIF('Opportunities'!$D$2:$D$143,$A4) | F4: =SUMIF('Opportunities'!$D$2:$D$143,$A4,'Opportunities'!$H$2:$H$143) | G4: =COUNTIFS('Opportunities'!$D$2:$D$143,$A4,'Opportunities'!$J$2:$J$143,">0") | H4: -
A5: https://betterwaste.co.uk/areas-we-cover/leicester/ | B5: Location | C5: OPTIMISE | D5: EASY | E5: =COUNTIF('Opportunities'!$D$2:$D$143,$A5) | F5: =SUMIF('Opportunities'!$D$2:$D$143,$A5,'Opportunities'!$H$2:$H$143) | G5: =COUNTIFS('Opportunities'!$D$2:$D$143,$A5,'Opportunities'!$J$2:$J$143,">0") | H5: -
A6: https://betterwaste.co.uk/areas-we-cover/liverpool/ | B6: Location | C6: CREATE | D6: EASY | E6: =COUNTIF('Opportunities'!$D$2:$D$143,$A6) | F6: =SUMIF('Opportunities'!$D$2:$D$143,$A6,'Opportunities'!$H$2:$H$143) | G6: =COUNTIFS('Opportunities'!$D$2:$D$143,$A6,'Opportunities'!$J$2:$J$143,">0") | H6: -
A7: https://betterwaste.co.uk/areas-we-cover/nottingham/ | B7: Location | C7: OPTIMISE | D7: EASY | E7: =COUNTIF('Opportunities'!$D$2:$D$143,$A7) | F7: =SUMIF('Opportunities'!$D$2:$D$143,$A7,'Opportunities'!$H$2:$H$143) | G7: =COUNTIFS('Opportunities'!$D$2:$D$143,$A7,'Opportunities'!$J$2:$J$143,">0") | H7: -
A8: https://betterwaste.co.uk/bakery-waste-management/ | B8: Sector | C8: OPTIMISE | D8: EASY | E8: =COUNTIF('Opportunities'!$D$2:$D$143,$A8) | F8: =SUMIF('Opportunities'!$D$2:$D$143,$A8,'Opportunities'!$H$2:$H$143) | G8: =COUNTIFS('Opportunities'!$D$2:$D$143,$A8,'Opportunities'!$J$2:$J$143,">0") | H8: 25
A9: https://betterwaste.co.uk/binpedia/ | B9: Gap vs competitors | C9: OPTIMISE | D9: EASY | E9: =COUNTIF('Opportunities'!$D$2:$D$143,$A9) | F9: =SUMIF('Opportunities'!$D$2:$D$143,$A9,'Opportunities'!$H$2:$H$143) | G9: =COUNTIFS('Opportunities'!$D$2:$D$143,$A9,'Opportunities'!$J$2:$J$143,">0") | H9: 39
A10: https://betterwaste.co.uk/bins/1100l-bin/ | B10: Gap vs competitors | C10: OPTIMISE | D10: EASY | E10: =COUNTIF('Opportunities'!$D$2:$D$143,$A10) | F10: =SUMIF('Opportunities'!$D$2:$D$143,$A10,'Opportunities'!$H$2:$H$143) | G10: =COUNTIFS('Opportunities'!$D$2:$D$143,$A10,'Opportunities'!$J$2:$J$143,">0") | H10: -
A11: https://betterwaste.co.uk/bins/240l-bin/ | B11: Gap vs competitors | C11: OPTIMISE | D11: EASY | E11: =COUNTIF('Opportunities'!$D$2:$D$143,$A11) | F11: =SUMIF('Opportunities'!$D$2:$D$143,$A11,'Opportunities'!$H$2:$H$143) | G11: =COUNTIFS('Opportunities'!$D$2:$D$143,$A11,'Opportunities'!$J$2:$J$143,">0") | H11: -
A12: https://betterwaste.co.uk/bins/360l-bin/ | B12: Gap vs competitors | C12: OPTIMISE | D12: EASY | E12: =COUNTIF('Opportunities'!$D$2:$D$143,$A12) | F12: =SUMIF('Opportunities'!$D$2:$D$143,$A12,'Opportunities'!$H$2:$H$143) | G12: =COUNTIFS('Opportunities'!$D$2:$D$143,$A12,'Opportunities'!$J$2:$J$143,">0") | H12: -
A13: https://betterwaste.co.uk/bins/660l-bin/ | B13: Gap vs competitors | C13: OPTIMISE | D13: EASY | E13: =COUNTIF('Opportunities'!$D$2:$D$143,$A13) | F13: =SUMIF('Opportunities'!$D$2:$D$143,$A13,'Opportunities'!$H$2:$H$143) | G13: =COUNTIFS('Opportunities'!$D$2:$D$143,$A13,'Opportunities'!$J$2:$J$143,">0") | H13: -
A14: https://betterwaste.co.uk/butchers-waste-collection/ | B14: Sector | C14: CREATE | D14: EASY | E14: =COUNTIF('Opportunities'!$D$2:$D$143,$A14) | F14: =SUMIF('Opportunities'!$D$2:$D$143,$A14,'Opportunities'!$H$2:$H$143) | G14: =COUNTIFS('Opportunities'!$D$2:$D$143,$A14,'Opportunities'!$J$2:$J$143,">0") | H14: -
A15: https://betterwaste.co.uk/cafe-waste-management/ | B15: Sector | C15: OPTIMISE | D15: EASY | E15: =COUNTIF('Opportunities'!$D$2:$D$143,$A15) | F15: =SUMIF('Opportunities'!$D$2:$D$143,$A15,'Opportunities'!$H$2:$H$143) | G15: =COUNTIFS('Opportunities'!$D$2:$D$143,$A15,'Opportunities'!$J$2:$J$143,">0") | H15: 19
A16: https://betterwaste.co.uk/commercial-skip-hire/ | B16: Gap vs competitors | C16: CREATE | D16: EASY | E16: =COUNTIF('Opportunities'!$D$2:$D$143,$A16) | F16: =SUMIF('Opportunities'!$D$2:$D$143,$A16,'Opportunities'!$H$2:$H$143) | G16: =COUNTIFS('Opportunities'!$D$2:$D$143,$A16,'Opportunities'!$J$2:$J$143,">0") | H16: -
A17: https://betterwaste.co.uk/confidential-waste/ | B17: Gap vs competitors | C17: CREATE | D17: EASY | E17: =COUNTIF('Opportunities'!$D$2:$D$143,$A17) | F17: =SUMIF('Opportunities'!$D$2:$D$143,$A17,'Opportunities'!$H$2:$H$143) | G17: =COUNTIFS('Opportunities'!$D$2:$D$143,$A17,'Opportunities'!$J$2:$J$143,">0") | H17: -
A18: https://betterwaste.co.uk/cooking-oil-collection/ | B18: Waste Type | C18: CREATE | D18: EASY | E18: =COUNTIF('Opportunities'!$D$2:$D$143,$A18) | F18: =SUMIF('Opportunities'!$D$2:$D$143,$A18,'Opportunities'!$H$2:$H$143) | G18: =COUNTIFS('Opportunities'!$D$2:$D$143,$A18,'Opportunities'!$J$2:$J$143,">0") | H18: -
A19: https://betterwaste.co.uk/dry-mixed-recycling-waste/ | B19: Gap vs competitors | C19: OPTIMISE | D19: EASY | E19: =COUNTIF('Opportunities'!$D$2:$D$143,$A19) | F19: =SUMIF('Opportunities'!$D$2:$D$143,$A19,'Opportunities'!$H$2:$H$143) | G19: =COUNTIFS('Opportunities'!$D$2:$D$143,$A19,'Opportunities'!$J$2:$J$143,">0") | H19: 57
A20: https://betterwaste.co.uk/hair-salon-waste-management/ | B20: Sector | C20: OPTIMISE | D20: EASY | E20: =COUNTIF('Opportunities'!$D$2:$D$143,$A20) | F20: =SUMIF('Opportunities'!$D$2:$D$143,$A20,'Opportunities'!$H$2:$H$143) | G20: =COUNTIFS('Opportunities'!$D$2:$D$143,$A20,'Opportunities'!$J$2:$J$143,">0") | H20: 21
A21: https://betterwaste.co.uk/it-equipment-disposal/ | B21: Gap vs competitors | C21: CREATE | D21: EASY | E21: =COUNTIF('Opportunities'!$D$2:$D$143,$A21) | F21: =SUMIF('Opportunities'!$D$2:$D$143,$A21,'Opportunities'!$H$2:$H$143) | G21: =COUNTIFS('Opportunities'!$D$2:$D$143,$A21,'Opportunities'!$J$2:$J$143,">0") | H21: -
A22: https://betterwaste.co.uk/metal-waste/ | B22: Waste Type | C22: CREATE | D22: EASY | E22: =COUNTIF('Opportunities'!$D$2:$D$143,$A22) | F22: =SUMIF('Opportunities'!$D$2:$D$143,$A22,'Opportunities'!$H$2:$H$143) | G22: =COUNTIFS('Opportunities'!$D$2:$D$143,$A22,'Opportunities'!$J$2:$J$143,">0") | H22: -
A23: https://betterwaste.co.uk/office-waste-management/ | B23: Gap vs competitors | C23: OPTIMISE | D23: EASY | E23: =COUNTIF('Opportunities'!$D$2:$D$143,$A23) | F23: =SUMIF('Opportunities'!$D$2:$D$143,$A23,'Opportunities'!$H$2:$H$143) | G23: =COUNTIFS('Opportunities'!$D$2:$D$143,$A23,'Opportunities'!$J$2:$J$143,">0") | H23: 65
A24: https://betterwaste.co.uk/paper-and-cardboard-waste/ | B24: Gap vs competitors | C24: OPTIMISE | D24: EASY | E24: =COUNTIF('Opportunities'!$D$2:$D$143,$A24) | F24: =SUMIF('Opportunities'!$D$2:$D$143,$A24,'Opportunities'!$H$2:$H$143) | G24: =COUNTIFS('Opportunities'!$D$2:$D$143,$A24,'Opportunities'!$J$2:$J$143,">0") | H24: 36
A25: https://betterwaste.co.uk/pub-waste-management/ | B25: Sector | C25: OPTIMISE | D25: EASY | E25: =COUNTIF('Opportunities'!$D$2:$D$143,$A25) | F25: =SUMIF('Opportunities'!$D$2:$D$143,$A25,'Opportunities'!$H$2:$H$143) | G25: =COUNTIFS('Opportunities'!$D$2:$D$143,$A25,'Opportunities'!$J$2:$J$143,">0") | H25: 13
A26: https://betterwaste.co.uk/restaurant-waste-management/ | B26: Sector | C26: OPTIMISE | D26: EASY | E26: =COUNTIF('Opportunities'!$D$2:$D$143,$A26) | F26: =SUMIF('Opportunities'!$D$2:$D$143,$A26,'Opportunities'!$H$2:$H$143) | G26: =COUNTIFS('Opportunities'!$D$2:$D$143,$A26,'Opportunities'!$J$2:$J$143,">0") | H26: 25
A27: https://betterwaste.co.uk/retail-waste-management/ | B27: Sector | C27: OPTIMISE | D27: EASY | E27: =COUNTIF('Opportunities'!$D$2:$D$143,$A27) | F27: =SUMIF('Opportunities'!$D$2:$D$143,$A27,'Opportunities'!$H$2:$H$143) | G27: =COUNTIFS('Opportunities'!$D$2:$D$143,$A27,'Opportunities'!$J$2:$J$143,">0") | H27: 45
A28: https://betterwaste.co.uk/sanitary-waste/ | B28: Waste Type | C28: CREATE | D28: EASY | E28: =COUNTIF('Opportunities'!$D$2:$D$143,$A28) | F28: =SUMIF('Opportunities'!$D$2:$D$143,$A28,'Opportunities'!$H$2:$H$143) | G28: =COUNTIFS('Opportunities'!$D$2:$D$143,$A28,'Opportunities'!$J$2:$J$143,">0") | H28: -
A29: https://betterwaste.co.uk/takeaway-waste-management/ | B29: Sector | C29: OPTIMISE | D29: EASY | E29: =COUNTIF('Opportunities'!$D$2:$D$143,$A29) | F29: =SUMIF('Opportunities'!$D$2:$D$143,$A29,'Opportunities'!$H$2:$H$143) | G29: =COUNTIFS('Opportunities'!$D$2:$D$143,$A29,'Opportunities'!$J$2:$J$143,">0") | H29: 15
A30: https://betterwaste.co.uk/wood-waste/ | B30: Waste Type | C30: CREATE | D30: EASY | E30: =COUNTIF('Opportunities'!$D$2:$D$143,$A30) | F30: =SUMIF('Opportunities'!$D$2:$D$143,$A30,'Opportunities'!$H$2:$H$143) | G30: =COUNTIFS('Opportunities'!$D$2:$D$143,$A30,'Opportunities'!$J$2:$J$143,">0") | H30: -
A31: https://betterwaste.co.uk/areas-we-cover/ | B31: Location | C31: OPTIMISE | D31: MEDIUM | E31: =COUNTIF('Opportunities'!$D$2:$D$143,$A31) | F31: =SUMIF('Opportunities'!$D$2:$D$143,$A31,'Opportunities'!$H$2:$H$143) | G31: =COUNTIFS('Opportunities'!$D$2:$D$143,$A31,'Opportunities'!$J$2:$J$143,">0") | H31: -
A32: https://betterwaste.co.uk/areas-we-cover/birmingham/ | B32: Location | C32: OPTIMISE | D32: MEDIUM | E32: =COUNTIF('Opportunities'!$D$2:$D$143,$A32) | F32: =SUMIF('Opportunities'!$D$2:$D$143,$A32,'Opportunities'!$H$2:$H$143) | G32: =COUNTIFS('Opportunities'!$D$2:$D$143,$A32,'Opportunities'!$J$2:$J$143,">0") | H32: 21
A33: https://betterwaste.co.uk/areas-we-cover/london/ | B33: Location | C33: OPTIMISE | D33: MEDIUM | E33: =COUNTIF('Opportunities'!$D$2:$D$143,$A33) | F33: =SUMIF('Opportunities'!$D$2:$D$143,$A33,'Opportunities'!$H$2:$H$143) | G33: =COUNTIFS('Opportunities'!$D$2:$D$143,$A33,'Opportunities'!$J$2:$J$143,">0") | H33: 28
A34: https://betterwaste.co.uk/areas-we-cover/manchester/ | B34: Location | C34: FIX | D34: MEDIUM | E34: =COUNTIF('Opportunities'!$D$2:$D$143,$A34) | F34: =SUMIF('Opportunities'!$D$2:$D$143,$A34,'Opportunities'!$H$2:$H$143) | G34: =COUNTIFS('Opportunities'!$D$2:$D$143,$A34,'Opportunities'!$J$2:$J$143,">0") | H34: 11
A35: https://betterwaste.co.uk/areas-we-cover/sheffield/ | B35: Location | C35: OPTIMISE | D35: MEDIUM | E35: =COUNTIF('Opportunities'!$D$2:$D$143,$A35) | F35: =SUMIF('Opportunities'!$D$2:$D$143,$A35,'Opportunities'!$H$2:$H$143) | G35: =COUNTIFS('Opportunities'!$D$2:$D$143,$A35,'Opportunities'!$J$2:$J$143,">0") | H35: -
A36: https://betterwaste.co.uk/binpedia/commercial-bin-sizes/ | B36: Informational | C36: CREATE | D36: MEDIUM | E36: =COUNTIF('Opportunities'!$D$2:$D$143,$A36) | F36: =SUMIF('Opportunities'!$D$2:$D$143,$A36,'Opportunities'!$H$2:$H$143) | G36: =COUNTIFS('Opportunities'!$D$2:$D$143,$A36,'Opportunities'!$J$2:$J$143,">0") | H36: -
A37: https://betterwaste.co.uk/care-home-waste-management/ | B37: Sector | C37: CREATE | D37: MEDIUM | E37: =COUNTIF('Opportunities'!$D$2:$D$143,$A37) | F37: =SUMIF('Opportunities'!$D$2:$D$143,$A37,'Opportunities'!$H$2:$H$143) | G37: =COUNTIFS('Opportunities'!$D$2:$D$143,$A37,'Opportunities'!$J$2:$J$143,">0") | H37: -
A38: https://betterwaste.co.uk/clinical-waste-disposal-clinical-waste-collection-companies/ | B38: Gap vs competitors | C38: OPTIMISE | D38: MEDIUM | E38: =COUNTIF('Opportunities'!$D$2:$D$143,$A38) | F38: =SUMIF('Opportunities'!$D$2:$D$143,$A38,'Opportunities'!$H$2:$H$143) | G38: =COUNTIFS('Opportunities'!$D$2:$D$143,$A38,'Opportunities'!$J$2:$J$143,">0") | H38: -
A39: https://betterwaste.co.uk/commercial-bin-collections/ | B39: Service | C39: OPTIMISE | D39: MEDIUM | E39: =COUNTIF('Opportunities'!$D$2:$D$143,$A39) | F39: =SUMIF('Opportunities'!$D$2:$D$143,$A39,'Opportunities'!$H$2:$H$143) | G39: =COUNTIFS('Opportunities'!$D$2:$D$143,$A39,'Opportunities'!$J$2:$J$143,">0") | H39: 54
A40: https://betterwaste.co.uk/commercial-waste-collection/ | B40: Gap vs competitors | C40: OPTIMISE | D40: MEDIUM | E40: =COUNTIF('Opportunities'!$D$2:$D$143,$A40) | F40: =SUMIF('Opportunities'!$D$2:$D$143,$A40,'Opportunities'!$H$2:$H$143) | G40: =COUNTIFS('Opportunities'!$D$2:$D$143,$A40,'Opportunities'!$J$2:$J$143,">0") | H40: 54
...

Sheet Fix List
A1: Priority | B1: Type | C1: Issue | D1: Evidence | E1: Impact | F1: Action
A2: P1 | B2: Redirect | C2: Manchester/London/Birmingham city pages: the "new" URLs 301 while the "-old" URLs serve 200 | D2: Crawl index: /areas-we-cover-old/manchester|london|birmingham/ all return 200; /areas-we-cover/manchester|london|birmingham/ all return 301. The -old pages hold the rankings because they are the only ones resolving | E2: ~3,000 SV of Manchester terms sitting on a deprecated URL | F2: VERIFY FIRST where the three 301s point, then either rename the -old URLs as canonical or fix the redirect. Do NOT blindly 301 old->new: that risks a loop
A3: P1 | B3: Canonicalisation | C3: www and non-www both indexed | D3: Ahrefs returns both betterwaste.co.uk/polystyrene-and-recycling/ and www.betterwaste.co.uk/polystyrene-and-recycling as separate ranking URLs; same for /business-waste-collections | E3: Link equity and ranking signals split across two hostnames | F3: Enforce one hostname via 301 + canonical + GSC property
A4: P1 | B4: Cannibalisation | C4: Two pages competing for the core money term | D4: business waste collection (2400 SV) ranks with /business-waste-collections/ at p26 AND /commercial-waste-management/ at p34 | E4: Neither page reaches top 20 | F4: Consolidate into one canonical money page; 301 the other
A5: P1 | B5: Content refresh | C5: Simpler Recycling page stuck just outside top 10 | D5: simpler recycling (1000 SV / KD 22) at p14 on /simpler-recycling-legislation-for-businesses-in-england-what-you-need-to-know/ | E5: Cheapest available win on the site | F5: Refresh content + internal links; target top 10
A6: P1 | B6: Sheet mapping | C6: Glass keywords mapped to the wrong page block | D6: Sheet rows 43-51 (glass waste terms) sit inside the /food-waste/ block; a live /glass-waste/ page already ranks p30-38 for them | E6: Mapping sheet misdirects the work | F6: Re-map all glass terms to /glass-waste/
A7: P2 | B7: Page mapping | C7: Location hub ranking for national service terms | D7: /areas-we-cover/ ranks for business refuse collection p5 (590 SV) + waste collection for business p59 + commercial waste services p54 + industrial waste collection p83 + waste disposal companies p63 | E7: Wrong page type for commercial head terms; caps conversion | F7: Build the national /commercial-waste-collection/ page and de-optimise the hub
A8: P2 | B8: Cannibalisation | C8: Blog post and service page competing | D8: commercial waste management companies ranks with the top-10 blog at p7 AND /business-waste-collections/ at p90 | E8: Service page suppressed by the blog | F8: Differentiate intent; internal-link blog to the service page
A9: P2 | B9: Internal linking | C9: Strongest page not passing equity to money pages | D9: /top-10-commercial-waste-management-companies-in-the-uk/ ranks 4-8 for ~20 head terms and is the site's top organic asset but is a competitor listicle | E9: Highest-authority page sends no equity to commercial pages, and names competitors to in-market users | F9: Add prominent internal links to the new commercial waste page
A10: P2 | B10: Duplicate ranking | C10: Several keywords returning two URLs from the same site | D10: business waste birmingham p19 and p26; commercial waste clearance birmingham p40 and p41; expanded polystyrene recycling p65 and p66; waste management companies london p29 and p32; zero waste to landfill p54 and p60; aluminium recycling p18 and p24 | E10: Diluted signals across near-duplicate pages | F10: Audit for duplicate/paginated variants and consolidate
A11: P3 | B11: Data hygiene | C11: Sheet volumes materially out of date vs Semrush | D11: dry mixed recycling bins listed 320, Semrush 1000; commercial cardboard waste listed 110, Semrush 480; commercial food waste disposal listed 210, Semrush 480 | E11: Prioritisation in the sheet is based on stale volumes | F11: Refresh all SV in the mapping sheet from Semrush UK
A12: P1 | B12: Cannibalisation | C12: Four live pages target overlapping commercial head terms | D12: /commercial-waste-collection/, /commercial-waste-management/, /business-waste-collections/ and /trade-waste-collections/ all return 200 and all target Cluster A terms | E12: Head terms split across four pages; none ranks | F12: Pick one canonical money page, 301 or de-optimise the other three
... A16: P3 | B16: Lost pages | C16: Four former pages now 404 and may hold links | D16: /better-waste-solutions-birmingham/, /better-waste-solutions-london/, /better-waste-solutions-manchester/, /business-waste-management-yorkshire/ | E16: Any inbound links are being wasted | F16: Check referring domains for each; 301 the ones with links to the relevant city or service page

Sheet Page Inventory
A1: URL | B1: HTTP | C1: Status | D1: Note
A2: EXISTS — I had scored these as CREATE
A3: /commercial-waste-collection/ | B3: 200 | C3: Exists | D3: The page the whole plan was built around. Optimisation, not a build
A4: /commercial-bin-collections/ | B4: 200 | C4: Exists | D4: I proposed /commercial-bins/
A5: /commercial-food-waste-collections/ | B5: 200 | C5: Exists
A6: /trade-waste-collections/ | B6: 200 | C6: Exists
A7: /office-waste-management/ | B7: 200 | C7: Exists
A8: /retail-waste-management/ | B8: 200 | C8: Exists
A9: /school-waste-management/ | B9: 200 | C9: Exists
A10: /hotel-waste-disposal/ | B10: 200 | C10: Exists | D10: I proposed /hotel-waste-management/
A11: /healthcare-waste/ | B11: 200 | C11: Exists | D11: Duplicates the clinical waste page
A12: /clinical-waste-disposal-clinical-waste-collection-companies/ | B12: 200 | C12: Exists | D12: AVOID-grade keywords. Re-point at commercial entry terms
A13: /bins/1100l-bin/ · 660l · 240l · 360l · fel · rel · roro | B13: 200 | C13: Exist (7) | D13: AVOID-grade retail intent. Keep as spec pages, drop the ranking target
A14: /areas-we-cover/ bradford · bristol · coventry · leeds · leicester · northampton · nottingham · sheffield | B14: 200 | C14: Exist (8) | D14: Eight city pages, none in the existing tracker
A16: REDIRECTING — verify before acting
A17: /areas-we-cover/manchester/ | B17: 301 | C17: Redirects | D17: The "-old" equivalent returns 200 and holds the rankings
A18: /areas-we-cover/london/ | B18: 301 | C18: Redirects | D18: Same
A19: /areas-we-cover/birmingham/ | B19: 301 | C19: Redirects | D19: Same
A20: /areas-we-cover-old/manchester/ · london · birmingham | B20: 200 | C20: Live | D20: These are the pages actually resolving and ranking
A22: GENUINELY MISSING — real build work
A23: /confidential-waste/ | B23: — | C23: Missing | D23: EASY · 5,600 SV
A24: /sanitary-waste/ | B24: — | C24: Missing | D24: EASY · 2,600 SV
A25: /industrial-waste/ | B25: — | C25: Missing | D25: MEDIUM · 1,110 SV
A26: /construction-waste/ | B26: — | C26: Missing | D26: MEDIUM · 850 SV
A27: /care-home-waste-management/ | B27: — | C27: Missing | D27: MEDIUM · 480 SV
A28: /dental-waste-disposal/ | B28: — | C28: Missing | D28: MEDIUM · 480 SV
A29: /it-equipment-disposal/ | B29: — | C29: Missing | D29: EASY · 2,490 SV — split out of the WEEE page, which is mostly AVOID/HARD
A30: /commercial-skip-hire/ | B30: — | C30: Missing | D30: EASY · 8,120 SV — check service fit first
A31: /wood-waste/ | B31: — | C31: Missing | D31: EASY · 390 SV
A32: /cooking-oil-collection/ | B32: — | C32: Missing | D32: EASY · 320 SV
A33: /butchers-waste-collection/ | B33: — | C33: Missing | D33: EASY · 260 SV
A34: /metal-waste/ | B34: — | C34: Missing | D34: EASY · 260 SV — check service model first
... A36: /areas-we-cover/glasgow/ | B36: — | C36: Missing | D36: EASY · 70 SV
A38: INDEX BLOAT — live 200s that should not be indexable
A39: /222-2/ · /test-2/ · /home/ · /thank-you/ · /thank-you-2/ · /trial-form/ · /demos/ | B39: 200 | C39: Live | D39: Remove or noindex
A40: /quote2-old/ · /quote-commercial-waste-old/ · /quote-waste-services-old/ | B40: 200 | C40: Live | D40: Superseded quote forms
A41: /quote2/?slink= (six parameter variants) | B41: 200 | C41: Live | D41: Add parameter handling
A42: /about · /binpedia · /contact-us · /blog · /faqs · /how-to-be-green | B42: 200 | C42: Live | D42: Also resolve with a trailing slash — pick one convention
A44: 404 — former pages that may hold links
A45: /better-waste-solutions-birmingham/ · -london/ · -manchester/ | B45: 404 | C45: Gone | D45: Check referring domains, then 301 to the city pages
...
